<?xml version="1.0"?>
<robot name="viratbot" xmlns:xacro="http://www.ros.org/wiki/xacro">
    <xacro:include filename="$(find viratbot_description)/urdf/viratbot.gazebo.xacro" />

    <link name="base_link"></link>


    <!-- Chassis -->
    <xacro:property name="c_m" value="10" />
    <xacro:property name="c_l" value="0.8" />
    <xacro:property name="c_b" value="0.4" />
    <xacro:property name="c_h" value="0.2" />
    
    <link name="chassis">

        <inertial>
            <mass value="10" />
            <inertia ixx="${((1/12)*c_m*(c_b*c_b + c_h*c_h)) + c_m*c_h/2*c_h/2}" ixy="0" ixz="0" iyy="${((1/12)*c_m*(c_l*c_l + c_h*c_h)) + c_m*c_h/2*c_h/2}" iyz="0" izz="${(1/12)*c_m*(c_b*c_b + c_l*c_l)}" />
            <origin xyz="0 0 0" rpy="0 0 0" />
        </inertial>

        <collision>
            <origin rpy="0 0 0" xyz="0 0 0.1" />
            <geometry>
                <box size="0.8 0.4 0.2" />
            </geometry>
        </collision>

        <visual>
            <origin rpy="0 0 0" xyz="-0.2 0 0" />
            <geometry>
                <mesh filename="package://viratbot_description/meshes/bot2.dae" scale="0.8 0.8 0.8" />
            </geometry>
        </visual>

    </link>

    <joint name="base_chassis_joint" type="fixed">
        <parent link="base_link" />
        <child link="chassis" />
        <origin xyz="0 0 0.14" rpy="0 0 0" />
    </joint>



    <!-- Caster Front -->
    <xacro:property name="cas_m" value="0.3" />
    <xacro:property name="cas_r" value="0.07" />

    <link name="caster">

        <inertial>
            <mass value="${cas_m}" />
            <inertia ixx="${(2/5)*cas_m*cas_r*cas_r}" ixy="0" ixz="0" iyy="${(2/5)*cas_m*cas_r*cas_r}" iyz="0" izz="${(2/5)*cas_m*cas_r*cas_r}" />
        </inertial>

        <collision>
            <origin xyz="0 0 0" rpy="0 0 0" />
            <geometry>
                <sphere radius="0.07" />
            </geometry>
        </collision>

        <visual>
            <origin xyz="0 0 0" rpy="0 0 0" />
            <geometry>
                <sphere radius="0.07" />
            </geometry>
        </visual>

        <visual>
            <origin xyz="0 0 0.08" rpy="0 0 0" />
            <geometry>
                <cylinder radius="0.01" length="0.05" />
            </geometry>
        </visual>

    </link>

    <joint name="caster_chassis_joint" type="fixed">

        <parent link="chassis" />
        <child link="caster" />
        <axis xyz="0 1 0" />
        <origin xyz="0.2 0 -0.07" rpy="0 0 0" />

    </joint>


    <!-- Left ad Right Wheels -->
    <xacro:property name="w_m" value="1" />
    <xacro:property name="w_r" value="0.14" />
    <xacro:property name="w_l" value="0.1" />

    <link name="right_wheel">

        <inertial>
            <mass value="1" />
            <inertia ixx="${(1/12)*w_m*(3*w_r*w_r + w_l*w_l)}" ixy="0" ixz="0" iyy="${(1/2)*w_m*w_r*w_r}" iyz="0" izz="${(1/12)*w_m*(3*w_r*w_r + w_l*w_l)}" />
            <origin xyz="0 0 0" rpy="0 1.5707 1.5707" />
        </inertial>

        <collision>
            <origin xyz="0 0 0" rpy="0 1.5707 1.5707" />
            <geometry>
                <cylinder radius="0.14" length="0.1" />
            </geometry>
        </collision>

        <visual>
            <origin xyz="0 0 0" rpy="0 1.5707 0" />
            <geometry>
                <mesh filename="package://viratbot_description/meshes/tyre1.dae" scale="1 1 1" />
            </geometry>
        </visual>

    </link>

    <link name="left_wheel">

        <inertial>
            <mass value="1" />
            <inertia ixx="${(1/12)*w_m*(3*w_r*w_r + w_l*w_l)}" ixy="0" ixz="0" iyy="${(1/2)*w_m*w_r*w_r}" iyz="0" izz="${(1/12)*w_m*(3*w_r*w_r + w_l*w_l)}" />
            <origin xyz="0 0 0" rpy="0 1.5707 1.5707" />
        </inertial>

        <collision>
            <origin xyz="0 0 0" rpy="0 1.5707 1.5707" />
            <geometry>
                <cylinder radius="0.14" length="0.1" />
            </geometry>
        </collision>

        <visual>
            <origin xyz="0 0 0" rpy="0 1.5707 0" />
            <geometry>
                <mesh filename="package://viratbot_description/meshes/tyre1.dae" scale="1 1 1" />
            </geometry>
        </visual>

    </link>


    <joint name="right_wheel_hinge" type="continuous">
        <parent link="chassis" />
        <child link="right_wheel" />
        <axis xyz="0 1 0" />
        <origin xyz="-0.2 0.26 0" rpy="0 0 0" />
    </joint>

    <joint name="left_wheel_hinge" type="continuous">
        <parent link="chassis" />
        <child link="left_wheel" />
        <axis xyz="0 1 0" />
        <origin xyz="-0.2 -0.26 0" rpy="0 0 0" />
    </joint>



    <!-- Camera -->
    <link name="camera">

        <inertial>
            <mass value="0.05" />
            <inertia ixx="0.0005" ixy="0" ixz="0" iyy="0.0005" iyz="0" izz="0.0005" />
        </inertial>

        <collision>
            <origin xyz="0 0 0" rpy="0 0 0" />
            <geometry>
                <box size="0.05 0.05 0.05" />
            </geometry>
        </collision>

        <visual>
            <origin xyz="0 0 0" rpy="0 0 0" />
            <geometry>
                <box size="0.05 0.05 0.05" />
            </geometry>
        </visual>

    </link>

    <joint name="camera_joint" type="fixed">

        <axis xyz="0 0 1" />
        <origin xyz="0.43 0 0.4" rpy="0 0.63 0" />
        <parent link="chassis" />
        <child link="camera" />

    </joint>

    <!-- Frame for reference -->
    <link name="camera_base"></link>
    <joint name="camera_b_chassis" type="fixed">
        <origin xyz="0.43 0 0" rpy="0 0 0" />
        <parent link="base_link" />
        <child link="camera_base" />
    </joint>

</robot>